{"name": "test_2", "status": "broken", "statusDetails": {"message": "Exception: FAKE EXCEPTION: This test fails on purpose.", "trace": "self = <test_suite.MyTestSuite testMethod=test_2>\n\n    @pytest.mark.expected_failure\n    def test_2(self):\n        print(\"\\n(This test fails on purpose)\")\n        self.open(\"https://xkcd.com/1675/\")\n>       raise Exception(\"FAKE EXCEPTION: This test fails on purpose.\")\nE       Exception: FAKE EXCEPTION: This test fails on purpose.\n\ntest_suite.py:20: Exception"}, "attachments": [{"name": "stdout", "source": "07b48dca-9a1a-41a8-881b-b692940cf148-attachment.txt", "type": "text/plain"}], "start": 1596662132106, "stop": 1596662140375, "uuid": "316edb85-229d-4812-a1ca-88536b8031ab", "historyId": "9fdbe35155c3a5e64f75caab6c4a4fb4", "testCaseId": "a1d283dcac6486ee2dfa6b8a9a9dd62e", "fullName": "test_suite.MyTestSuite#test_2", "labels": [{"name": "tag", "value": "expected_failure"}, {"name": "suite", "value": "test_suite"}, {"name": "subSuite", "value": "MyTestSuite"}, {"name": "host", "value": "CAL4PFMXT2"}, {"name": "thread", "value": "24144-MainThread"}, {"name": "framework", "value": "pytest"}, {"name": "language", "value": "cpython3"}, {"name": "package", "value": "test_suite"}]}