{"name": "test_2", "status": "broken", "statusDetails": {"message": "Exception: FAKE EXCEPTION: This test fails on purpose.", "trace": "self = <test_suite.MyTestSuite testMethod=test_2>\n\n    @pytest.mark.expected_failure\n    def test_2(self):\n        print(\"\\n(This test fails on purpose)\")\n        self.open(\"https://xkcd.com/1675/\")\n>       raise Exception(\"FAKE EXCEPTION: This test fails on purpose.\")\nE       Exception: FAKE EXCEPTION: This test fails on purpose.\n\ntest_suite.py:20: Exception"}, "attachments": [{"name": "stdout", "source": "60dfc9cd-6555-463a-a1e4-9577bb94dbd6-attachment.txt", "type": "text/plain"}], "start": 1596657845284, "stop": 1596657854636, "uuid": "f5e903f6-b6db-4203-9f2f-c17d1a4e6a8d", "historyId": "9fdbe35155c3a5e64f75caab6c4a4fb4", "testCaseId": "a1d283dcac6486ee2dfa6b8a9a9dd62e", "fullName": "test_suite.MyTestSuite#test_2", "labels": [{"name": "tag", "value": "expected_failure"}, {"name": "suite", "value": "test_suite"}, {"name": "subSuite", "value": "MyTestSuite"}, {"name": "host", "value": "CAL4PFMXT2"}, {"name": "thread", "value": "22576-MainThread"}, {"name": "framework", "value": "pytest"}, {"name": "language", "value": "cpython3"}, {"name": "package", "value": "test_suite"}]}